  <robot name="baxter">
      <material name="black">
          <texture />
          <color rgba="0 0 0 1" />
      </material>
      <material name="blue">
          <texture />
          <color rgba="0 0 1 0.8" />
      </material>
      <material name="darkgray">
          <texture />
          <color rgba="0.2 0.2 0.2 1" />
      </material>
      <material name="darkred">
          <texture />
          <color rgba="0.5 0.1 0.1 1" />
      </material>
      <material name="lightgrey">
          <texture />
          <color rgba="0.1 0.1 0.1 1" />
      </material>
      <material name="red">
          <texture />
          <color rgba="0.8 0.3 0.3 0.3" />
      </material>
      <link name="base">
          <inertial>
              <mass value="0.0001" />
              <origin xyz="0 0 0" rpy="0 -0 0" />
              <inertia ixx="1e-08" ixy="0" ixz="0" iyy="1e-08" iyz="0" izz="1e-08" />
          </inertial>
      </link>
      <link name="collision_head_link_1">
          <inertial>
              <mass value="0.0001" />
              <origin xyz="0 0 0" rpy="0 -0 0" />
              <inertia ixx="1e-08" ixy="0" ixz="0" iyy="1e-08" iyz="0" izz="1e-08" />
          </inertial>
          <visual>
              <origin xyz="0 0 0" rpy="0 -0 0" />
              <geometry>
                  <sphere radius="0.001" />
              </geometry>
              <material name="red">
                  <texture />
                  <color rgba="0.8 0.3 0.3 0.3" />
              </material>
          </visual>
          <collision>
              <origin xyz="-0.07 -0.04 0" rpy="0 -0 0" />
              <geometry>
                  <sphere radius="0.22" />
              </geometry>
          </collision>
      </link>
      <link name="collision_head_link_2">
          <inertial>
              <mass value="0.0001" />
              <origin xyz="0 0 0" rpy="0 -0 0" />
              <inertia ixx="1e-08" ixy="0" ixz="0" iyy="1e-08" iyz="0" izz="1e-08" />
          </inertial>
          <visual>
              <origin xyz="0 0 0" rpy="0 -0 0" />
              <geometry>
                  <sphere radius="0.001" />
              </geometry>
              <material name="red">
                  <texture />
                  <color rgba="0.8 0.3 0.3 0.3" />
              </material>
          </visual>
          <collision>
              <origin xyz="-0.07 0.04 0" rpy="0 -0 0" />
              <geometry>
                  <sphere radius="0.22" />
              </geometry>
          </collision>
      </link>
      <link name="display">
          <inertial>
              <mass value="0.0001" />
              <origin xyz="0 0 0" rpy="0 -0 0" />
              <inertia ixx="1e-08" ixy="0" ixz="0" iyy="1e-08" iyz="0" izz="1e-08" />
          </inertial>
          <visual>
              <origin xyz="0 0 0" rpy="0.261799 -0 0" />
              <geometry>
                  <box size="0.218 0.16 0.001" />
              </geometry>
              <material name="black">
                  <texture />
                  <color rgba="0 0 0 1" />
              </material>
          </visual>
      </link>
      <link name="dummyhead1">
          <inertial>
              <mass value="0.0001" />
              <origin xyz="0 0 0" rpy="0 -0 0" />
              <inertia ixx="1e-08" ixy="0" ixz="0" iyy="1e-08" iyz="0" izz="1e-08" />
          </inertial>
      </link>
      <link name="head">
          <inertial>
              <mass value="0.547767" />
              <origin xyz="0 0 0" rpy="0 -0 0" />
              <inertia ixx="0.004641" ixy="0.000159" ixz="0.000242" iyy="0.003295" iyz="-0.001324" izz="0.003415" />
          </inertial>
          <visual>
              <origin xyz="0 0 0.00953" rpy="0 -0 0" />
              <geometry>
                  <mesh filename="package://baxter_description/meshes/head/H0.DAE" scale="1 1 1" />
              </geometry>
              <material name="darkgray">
                  <texture />
                  <color rgba="0.2 0.2 0.2 1" />
              </material>
          </visual>
          <collision>
              <origin xyz="0 0 0" rpy="0 -0 0" />
              <geometry>
                  <sphere radius="0.001" />
              </geometry>
          </collision>
      </link>
      <link name="head_camera">
          <inertial>
              <mass value="0.0001" />
              <origin xyz="0 0 0" rpy="0 -0 0" />
              <inertia ixx="1e-08" ixy="0" ixz="0" iyy="1e-08" iyz="0" izz="1e-08" />
          </inertial>
      </link>
      <link name="left_arm_itb">
          <inertial>
              <mass value="0.0001" />
              <origin xyz="0 0 0" rpy="0 -0 0" />
              <inertia ixx="1e-08" ixy="0" ixz="0" iyy="1e-08" iyz="0" izz="1e-08" />
          </inertial>
      </link>
      <link name="left_arm_mount">
          <inertial>
              <mass value="0.0001" />
              <origin xyz="0 0 0" rpy="0 -0 0" />
              <inertia ixx="1e-08" ixy="0" ixz="0" iyy="1e-08" iyz="0" izz="1e-08" />
          </inertial>
      </link>
      <link name="left_gripper">
          <inertial>
              <mass value="0.0001" />
              <origin xyz="0 0 0" rpy="0 -0 0" />
              <inertia ixx="1e-08" ixy="0" ixz="0" iyy="1e-08" iyz="0" izz="1e-08" />
          </inertial>
          <visual>
              <origin xyz="0 0 0" rpy="0 -0 0" />
              <geometry>
                  <box size="0.01 0.01 0.01" />
              </geometry>
              <material name="black">
                  <texture />
                  <color rgba="0 0 0 1" />
              </material>
          </visual>
      </link>
      <link name="left_gripper_base">
          <inertial>
              <mass value="0.28" />
              <origin xyz="0.0014 0 0.024" rpy="0 -0 0" />
              <inertia ixx="0" ixy="0" ixz="0" iyy="0" iyz="0" izz="0" />
          </inertial>
          <visual>
              <origin xyz="0.0014 0 0.024" rpy="0 -0 0" />
              <geometry>
                  <mesh filename="package://baxter_description/meshes/electric_gripper/electric_gripper_w_fingers.DAE" scale="1 1 1" />
              </geometry>
              <material name="darkred">
                  <texture />
                  <color rgba="0.5 0.1 0.1 1" />
              </material>
          </visual>
      </link>
      <link name="left_hand">
          <inertial>
              <mass value="0.19125" />
              <origin xyz="0.01093 0.00042 -0.01532" rpy="0 -0 0" />
              <inertia ixx="0.00017588" ixy="1.47073e-06" ixz="2.43633e-05" iyy="0.000211664" iyz="1.72689e-06" izz="0.000237454" />
          </inertial>
          <collision>
              <origin xyz="0 0 -0.0232" rpy="0 -0 0" />
              <geometry>
                  <cylinder radius="0.04" length="0.0464" />
              </geometry>
          </collision>
      </link>
      <link name="left_hand_accelerometer">
          <inertial>
              <mass value="0.0001" />
              <origin xyz="0 0 0" rpy="0 -0 0" />
              <inertia ixx="1e-08" ixy="0" ixz="0" iyy="1e-08" iyz="0" izz="1e-08" />
          </inertial>
          <visual>
              <origin xyz="0 0 0" rpy="0 -0 0" />
              <geometry>
                  <box size="0.01 0.01 0.01" />
              </geometry>
              <material name="black">
                  <texture />
                  <color rgba="0 0 0 1" />
              </material>
          </visual>
      </link>
      <link name="left_hand_camera">
          <inertial>
              <mass value="0.0001" />
              <origin xyz="0 0 0" rpy="0 -0 0" />
              <inertia ixx="1e-08" ixy="0" ixz="0" iyy="1e-08" iyz="0" izz="1e-08" />
          </inertial>
          <visual>
              <origin xyz="0 0 0" rpy="0 -0 0" />
              <geometry>
                  <cylinder radius="0.02" length="0.01" />
              </geometry>
              <material name="blue">
                  <texture />
                  <color rgba="0 0 1 0.8" />
              </material>
          </visual>
      </link>
      <link name="left_hand_camera_axis">
          <inertial>
              <mass value="0.0001" />
              <origin xyz="0 0 0" rpy="0 -0 0" />
              <inertia ixx="1e-08" ixy="0" ixz="0" iyy="1e-08" iyz="0" izz="1e-08" />
          </inertial>
      </link>
      <link name="left_hand_range">
          <inertial>
              <mass value="0.0001" />
              <origin xyz="0 0 0" rpy="0 -0 0" />
              <inertia ixx="1e-08" ixy="0" ixz="0" iyy="1e-08" iyz="0" izz="1e-08" />
          </inertial>
          <visual>
              <origin xyz="0 0 0" rpy="0 -0 0" />
              <geometry>
                  <box size="0.005 0.02 0.005" />
              </geometry>
              <material name="blue">
                  <texture />
                  <color rgba="0 0 1 0.8" />
              </material>
          </visual>
      </link>
      <link name="left_lower_elbow">
          <inertial>
              <mass value="2.07206" />
              <origin xyz="0.02611 0.00159 -0.01117" rpy="0 -0 0" />
              <inertia ixx="0.00711583" ixy="0.000360362" ixz="0.00074595" iyy="0.0131823" iyz="-0.000196634" izz="0.00926852" />
          </inertial>
          <visual>
              <origin xyz="0 0 0" rpy="0 -0 0" />
              <geometry>
                  <mesh filename="package://baxter_description/meshes/lower_elbow/E1.DAE" scale="1 1 1" />
              </geometry>
              <material name="darkred">
                  <texture />
                  <color rgba="0.5 0.1 0.1 1" />
              </material>
          </visual>
          <collision>
              <origin xyz="0 0 0" rpy="0 -0 0" />
              <geometry>
                  <cylinder radius="0.06" length="0.1" />
              </geometry>
          </collision>
      </link>
      <link name="left_lower_forearm">
          <inertial>
              <mass value="1.60979" />
              <origin xyz="0.06041 0.00697 0.006" rpy="0 -0 0" />
              <inertia ixx="0.00387607" ixy="-0.000443848" ixz="-0.00021115" iyy="0.00700538" iyz="0.000153481" izz="0.00552755" />
          </inertial>
          <visual>
              <origin xyz="0 0 0" rpy="0 -0 0" />
              <geometry>
                  <mesh filename="package://baxter_description/meshes/lower_forearm/W1.DAE" scale="1 1 1" />
              </geometry>
              <material name="darkred">
                  <texture />
                  <color rgba="0.5 0.1 0.1 1" />
              </material>
          </visual>
          <collision>
              <origin xyz="0 0 0" rpy="0 -0 0" />
              <geometry>
                  <cylinder radius="0.06" length="0.1" />
              </geometry>
          </collision>
      </link>
      <link name="left_lower_shoulder">
          <inertial>
              <mass value="3.22698" />
              <origin xyz="0.06845 0.00269 -0.00529" rpy="0 -0 0" />
              <inertia ixx="0.0117521" ixy="-0.000300964" ixz="0.00207676" iyy="0.027886" iyz="-0.00018822" izz="0.0207875" />
          </inertial>
          <visual>
              <origin xyz="0 0 0" rpy="0 -0 0" />
              <geometry>
                  <mesh filename="package://baxter_description/meshes/lower_shoulder/S1.DAE" scale="1 1 1" />
              </geometry>
              <material name="darkred">
                  <texture />
                  <color rgba="0.5 0.1 0.1 1" />
              </material>
          </visual>
          <collision>
              <origin xyz="0 0 0" rpy="0 -0 0" />
              <geometry>
                  <cylinder radius="0.06" length="0.12" />
              </geometry>
          </collision>
      </link>
      <link name="left_torso_itb">
          <inertial>
              <mass value="0.0001" />
              <origin xyz="0 0 0" rpy="0 -0 0" />
              <inertia ixx="1e-08" ixy="0" ixz="0" iyy="1e-08" iyz="0" izz="1e-08" />
          </inertial>
      </link>
      <link name="left_upper_elbow">
          <inertial>
              <mass value="4.31272" />
              <origin xyz="-0.00276 0.00132 0.18086" rpy="0 -0 0" />
              <inertia ixx="0.0266173" ixy="0.000292706" ixz="0.0039219" iyy="0.0284436" iyz="0.00108389" izz="0.0124801" />
          </inertial>
          <visual>
              <origin xyz="0 0 0" rpy="0 -0 0" />
              <geometry>
                  <mesh filename="package://baxter_description/meshes/upper_elbow/E0.DAE" scale="1 1 1" />
              </geometry>
              <material name="darkred">
                  <texture />
                  <color rgba="0.5 0.1 0.1 1" />
              </material>
          </visual>
          <collision>
              <origin xyz="0 0 -0.0535" rpy="0 -0 0" />
              <geometry>
                  <cylinder radius="0.06" length="0.107" />
              </geometry>
          </collision>
      </link>
      <link name="left_upper_elbow_visual">
          <inertial>
              <mass value="0.0001" />
              <origin xyz="0 0 0" rpy="0 -0 0" />
              <inertia ixx="1e-08" ixy="0" ixz="0" iyy="1e-08" iyz="0" izz="1e-08" />
          </inertial>
          <collision>
              <origin xyz="0 0 0.1365" rpy="0 -0 0" />
              <geometry>
                  <cylinder radius="0.06" length="0.273" />
              </geometry>
          </collision>
      </link>
      <link name="left_upper_forearm">
          <inertial>
              <mass value="2.24665" />
              <origin xyz="-0.00168 0.0046 0.13952" rpy="0 -0 0" />
              <inertia ixx="0.0166774" ixy="0.000184037" ixz="0.000186576" iyy="0.0167546" iyz="-0.000647324" izz="0.00374631" />
          </inertial>
          <visual>
              <origin xyz="0 0 0" rpy="0 -0 0" />
              <geometry>
                  <mesh filename="package://baxter_description/meshes/upper_forearm/W0.DAE" scale="1 1 1" />
              </geometry>
              <material name="darkred">
                  <texture />
                  <color rgba="0.5 0.1 0.1 1" />
              </material>
          </visual>
          <collision>
              <origin xyz="0 0 -0.044" rpy="0 -0 0" />
              <geometry>
                  <cylinder radius="0.06" length="0.088" />
              </geometry>
          </collision>
      </link>
      <link name="left_upper_forearm_visual">
          <inertial>
              <mass value="0.0001" />
              <origin xyz="0 0 0" rpy="0 -0 0" />
              <inertia ixx="1e-08" ixy="0" ixz="0" iyy="1e-08" iyz="0" izz="1e-08" />
          </inertial>
          <collision>
              <origin xyz="0 0 0.136" rpy="0 -0 0" />
              <geometry>
                  <cylinder radius="0.06" length="0.272" />
              </geometry>
          </collision>
      </link>
      <link name="left_upper_shoulder">
          <inertial>
              <mass value="5.70044" />
              <origin xyz="0.01783 0.00086 0.19127" rpy="0 -0 0" />
              <inertia ixx="0.047091" ixy="0.000127876" ixz="0.0061487" iyy="0.0376698" iyz="0.000780869" izz="0.0359599" />
          </inertial>
          <visual>
              <origin xyz="0 0 0" rpy="0 -0 0" />
              <geometry>
                  <mesh filename="package://baxter_description/meshes/upper_shoulder/S0.DAE" scale="1 1 1" />
              </geometry>
              <material name="darkred">
                  <texture />
                  <color rgba="0.5 0.1 0.1 1" />
              </material>
          </visual>
          <collision>
              <origin xyz="0 0 0.1361" rpy="0 -0 0" />
              <geometry>
                  <cylinder radius="0.06" length="0.2722" />
              </geometry>
          </collision>
      </link>
      <link name="left_wrist">
          <inertial>
              <mass value="0.35093" />
              <origin xyz="0.00198 0.00125 0.01855" rpy="0 -0 0" />
              <inertia ixx="0.000252892" ixy="5.75311e-06" ixz="-1.59345e-06" iyy="0.00026886" iyz="-5.19818e-06" izz="0.000307412" />
          </inertial>
          <visual>
              <origin xyz="0 0 0" rpy="0 -0 0" />
              <geometry>
                  <mesh filename="package://baxter_description/meshes/wrist/W2.DAE" scale="1 1 1" />
              </geometry>
              <material name="lightgrey">
                  <texture />
                  <color rgba="0.1 0.1 0.1 1" />
              </material>
          </visual>
          <collision>
              <origin xyz="0 0 0" rpy="0 -0 0" />
              <geometry>
                  <cylinder radius="0.06" length="0.165" />
              </geometry>
          </collision>
      </link>
      <link name="pedestal">
          <inertial>
              <mass value="60.864" />
              <origin xyz="0 0 0" rpy="0 -0 0" />
              <inertia ixx="5.06359" ixy="0.00103417" ixz="0.801996" iyy="6.08689" iyz="0.00105311" izz="4.96192" />
          </inertial>
          <visual>
              <origin xyz="0 0 0" rpy="0 -0 0" />
              <geometry>
                  <mesh filename="package://baxter_description/meshes/base/PEDESTAL.DAE" scale="1 1 1" />
              </geometry>
              <material name="darkgray">
                  <texture />
                  <color rgba="0.2 0.2 0.2 1" />
              </material>
          </visual>
          <collision>
              <origin xyz="-0.04 0 -0.775" rpy="0 -0 0" />
              <geometry>
                  <box size="0.92 0.83 0.3" />
              </geometry>
          </collision>
      </link>
      <link name="right_arm_itb">
          <inertial>
              <mass value="0.0001" />
              <origin xyz="0 0 0" rpy="0 -0 0" />
              <inertia ixx="1e-08" ixy="0" ixz="0" iyy="1e-08" iyz="0" izz="1e-08" />
          </inertial>
      </link>
      <link name="right_arm_mount">
          <inertial>
              <mass value="0.0001" />
              <origin xyz="0 0 0" rpy="0 -0 0" />
              <inertia ixx="1e-08" ixy="0" ixz="0" iyy="1e-08" iyz="0" izz="1e-08" />
          </inertial>
      </link>
      <link name="right_gripper">
          <inertial>
              <mass value="0.0001" />
              <origin xyz="0 0 0" rpy="0 -0 0" />
              <inertia ixx="1e-08" ixy="0" ixz="0" iyy="1e-08" iyz="0" izz="1e-08" />
          </inertial>
          <visual>
              <origin xyz="0 0 0" rpy="0 -0 0" />
              <geometry>
                  <box size="0.01 0.01 0.01" />
              </geometry>
              <material name="black">
                  <texture />
                  <color rgba="0 0 0 1" />
              </material>
          </visual>
      </link>
      <link name="right_gripper_base">
          <inertial>
              <mass value="0.28" />
              <origin xyz="0.0014 0 0.024" rpy="0 -0 0" />
              <inertia ixx="0" ixy="0" ixz="0" iyy="0" iyz="0" izz="0" />
          </inertial>
          <visual>
              <origin xyz="0.0014 0 0.024" rpy="0 -0 0" />
              <geometry>
                  <mesh filename="package://baxter_description/meshes/electric_gripper/electric_gripper_w_fingers.DAE" scale="1 1 1" />
              </geometry>
              <material name="darkred">
                  <texture />
                  <color rgba="0.5 0.1 0.1 1" />
              </material>
          </visual>
      </link>
      <link name="right_hand">
          <inertial>
              <mass value="0.19125" />
              <origin xyz="0.01093 0.00042 -0.01532" rpy="0 -0 0" />
              <inertia ixx="0.00017588" ixy="1.47073e-06" ixz="2.43633e-05" iyy="0.000211664" iyz="1.72689e-06" izz="0.000237454" />
          </inertial>
          <collision>
              <origin xyz="0 0 -0.0232" rpy="0 -0 0" />
              <geometry>
                  <cylinder radius="0.04" length="0.0464" />
              </geometry>
          </collision>
      </link>
      <link name="right_hand_accelerometer">
          <inertial>
              <mass value="0.0001" />
              <origin xyz="0 0 0" rpy="0 -0 0" />
              <inertia ixx="1e-08" ixy="0" ixz="0" iyy="1e-08" iyz="0" izz="1e-08" />
          </inertial>
          <visual>
              <origin xyz="0 0 0" rpy="0 -0 0" />
              <geometry>
                  <box size="0.01 0.01 0.01" />
              </geometry>
              <material name="black">
                  <texture />
                  <color rgba="0 0 0 1" />
              </material>
          </visual>
      </link>
      <link name="right_hand_camera">
          <inertial>
              <mass value="0.0001" />
              <origin xyz="0 0 0" rpy="0 -0 0" />
              <inertia ixx="1e-08" ixy="0" ixz="0" iyy="1e-08" iyz="0" izz="1e-08" />
          </inertial>
          <visual>
              <origin xyz="0 0 0" rpy="0 -0 0" />
              <geometry>
                  <cylinder radius="0.02" length="0.01" />
              </geometry>
              <material name="blue">
                  <texture />
                  <color rgba="0 0 1 0.8" />
              </material>
          </visual>
      </link>
      <link name="right_hand_camera_axis">
          <inertial>
              <mass value="0.0001" />
              <origin xyz="0 0 0" rpy="0 -0 0" />
              <inertia ixx="1e-08" ixy="0" ixz="0" iyy="1e-08" iyz="0" izz="1e-08" />
          </inertial>
      </link>
      <link name="right_hand_range">
          <inertial>
              <mass value="0.0001" />
              <origin xyz="0 0 0" rpy="0 -0 0" />
              <inertia ixx="1e-08" ixy="0" ixz="0" iyy="1e-08" iyz="0" izz="1e-08" />
          </inertial>
          <visual>
              <origin xyz="0 0 0" rpy="0 -0 0" />
              <geometry>
                  <box size="0.005 0.02 0.005" />
              </geometry>
              <material name="blue">
                  <texture />
                  <color rgba="0 0 1 0.8" />
              </material>
          </visual>
      </link>
      <link name="right_lower_elbow">
          <inertial>
              <mass value="2.07206" />
              <origin xyz="0.02611 0.00159 -0.01117" rpy="0 -0 0" />
              <inertia ixx="0.00711583" ixy="0.000360362" ixz="0.00074595" iyy="0.0131823" iyz="-0.000196634" izz="0.00926852" />
          </inertial>
          <visual>
              <origin xyz="0 0 0" rpy="0 -0 0" />
              <geometry>
                  <mesh filename="package://baxter_description/meshes/lower_elbow/E1.DAE" scale="1 1 1" />
              </geometry>
              <material name="darkred">
                  <texture />
                  <color rgba="0.5 0.1 0.1 1" />
              </material>
          </visual>
          <collision>
              <origin xyz="0 0 0" rpy="0 -0 0" />
              <geometry>
                  <cylinder radius="0.06" length="0.1" />
              </geometry>
          </collision>
      </link>
      <link name="right_lower_forearm">
          <inertial>
              <mass value="1.60979" />
              <origin xyz="0.06041 0.00697 0.006" rpy="0 -0 0" />
              <inertia ixx="0.00387607" ixy="-0.000443848" ixz="-0.00021115" iyy="0.00700538" iyz="0.000153481" izz="0.00552755" />
          </inertial>
          <visual>
              <origin xyz="0 0 0" rpy="0 -0 0" />
              <geometry>
                  <mesh filename="package://baxter_description/meshes/lower_forearm/W1.DAE" scale="1 1 1" />
              </geometry>
              <material name="darkred">
                  <texture />
                  <color rgba="0.5 0.1 0.1 1" />
              </material>
          </visual>
          <collision>
              <origin xyz="0 0 0" rpy="0 -0 0" />
              <geometry>
                  <cylinder radius="0.06" length="0.1" />
              </geometry>
          </collision>
      </link>
      <link name="right_lower_shoulder">
          <inertial>
              <mass value="3.22698" />
              <origin xyz="0.06845 0.00269 -0.00529" rpy="0 -0 0" />
              <inertia ixx="0.0117521" ixy="-0.000300964" ixz="0.00207676" iyy="0.027886" iyz="-0.00018822" izz="0.0207875" />
          </inertial>
          <visual>
              <origin xyz="0 0 0" rpy="0 -0 0" />
              <geometry>
                  <mesh filename="package://baxter_description/meshes/lower_shoulder/S1.DAE" scale="1 1 1" />
              </geometry>
              <material name="darkred">
                  <texture />
                  <color rgba="0.5 0.1 0.1 1" />
              </material>
          </visual>
          <collision>
              <origin xyz="0 0 0" rpy="0 -0 0" />
              <geometry>
                  <cylinder radius="0.06" length="0.12" />
              </geometry>
          </collision>
      </link>
      <link name="right_torso_itb">
          <inertial>
              <mass value="0.0001" />
              <origin xyz="0 0 0" rpy="0 -0 0" />
              <inertia ixx="1e-08" ixy="0" ixz="0" iyy="1e-08" iyz="0" izz="1e-08" />
          </inertial>
      </link>
      <link name="right_upper_elbow">
          <inertial>
              <mass value="4.31272" />
              <origin xyz="-0.00276 0.00132 0.18086" rpy="0 -0 0" />
              <inertia ixx="0.0266173" ixy="0.000292706" ixz="0.0039219" iyy="0.0284436" iyz="0.00108389" izz="0.0124801" />
          </inertial>
          <visual>
              <origin xyz="0 0 0" rpy="0 -0 0" />
              <geometry>
                  <mesh filename="package://baxter_description/meshes/upper_elbow/E0.DAE" scale="1 1 1" />
              </geometry>
              <material name="darkred">
                  <texture />
                  <color rgba="0.5 0.1 0.1 1" />
              </material>
          </visual>
          <collision>
              <origin xyz="0 0 -0.0535" rpy="0 -0 0" />
              <geometry>
                  <cylinder radius="0.06" length="0.107" />
              </geometry>
          </collision>
      </link>
      <link name="right_upper_elbow_visual">
          <inertial>
              <mass value="0.0001" />
              <origin xyz="0 0 0" rpy="0 -0 0" />
              <inertia ixx="1e-08" ixy="0" ixz="0" iyy="1e-08" iyz="0" izz="1e-08" />
          </inertial>
          <collision>
              <origin xyz="0 0 0.1365" rpy="0 -0 0" />
              <geometry>
                  <cylinder radius="0.06" length="0.273" />
              </geometry>
          </collision>
      </link>
      <link name="right_upper_forearm">
          <inertial>
              <mass value="2.24665" />
              <origin xyz="-0.00168 0.0046 0.13952" rpy="0 -0 0" />
              <inertia ixx="0.0166774" ixy="0.000184037" ixz="0.000186576" iyy="0.0167546" iyz="-0.000647324" izz="0.00374631" />
          </inertial>
          <visual>
              <origin xyz="0 0 0" rpy="0 -0 0" />
              <geometry>
                  <mesh filename="package://baxter_description/meshes/upper_forearm/W0.DAE" scale="1 1 1" />
              </geometry>
              <material name="darkred">
                  <texture />
                  <color rgba="0.5 0.1 0.1 1" />
              </material>
          </visual>
          <collision>
              <origin xyz="0 0 -0.044" rpy="0 -0 0" />
              <geometry>
                  <cylinder radius="0.06" length="0.088" />
              </geometry>
          </collision>
      </link>
      <link name="right_upper_forearm_visual">
          <inertial>
              <mass value="0.0001" />
              <origin xyz="0 0 0" rpy="0 -0 0" />
              <inertia ixx="1e-08" ixy="0" ixz="0" iyy="1e-08" iyz="0" izz="1e-08" />
          </inertial>
          <collision>
              <origin xyz="0 0 0.136" rpy="0 -0 0" />
              <geometry>
                  <cylinder radius="0.06" length="0.272" />
              </geometry>
          </collision>
      </link>
      <link name="right_upper_shoulder">
          <inertial>
              <mass value="5.70044" />
              <origin xyz="0.01783 0.00086 0.19127" rpy="0 -0 0" />
              <inertia ixx="0.047091" ixy="0.000127876" ixz="0.0061487" iyy="0.0376698" iyz="0.000780869" izz="0.0359599" />
          </inertial>
          <visual>
              <origin xyz="0 0 0" rpy="0 -0 0" />
              <geometry>
                  <mesh filename="package://baxter_description/meshes/upper_shoulder/S0.DAE" scale="1 1 1" />
              </geometry>
              <material name="darkred">
                  <texture />
                  <color rgba="0.5 0.1 0.1 1" />
              </material>
          </visual>
          <collision>
              <origin xyz="0 0 0.1361" rpy="0 -0 0" />
              <geometry>
                  <cylinder radius="0.06" length="0.2722" />
              </geometry>
          </collision>
      </link>
      <link name="right_wrist">
          <inertial>
              <mass value="0.35093" />
              <origin xyz="0.00198 0.00125 0.01855" rpy="0 -0 0" />
              <inertia ixx="0.000252892" ixy="5.75311e-06" ixz="-1.59345e-06" iyy="0.00026886" iyz="-5.19818e-06" izz="0.000307412" />
          </inertial>
          <visual>
              <origin xyz="0 0 0" rpy="0 -0 0" />
              <geometry>
                  <mesh filename="package://baxter_description/meshes/wrist/W2.DAE" scale="1 1 1" />
              </geometry>
              <material name="lightgrey">
                  <texture />
                  <color rgba="0.1 0.1 0.1 1" />
              </material>
          </visual>
          <collision>
              <origin xyz="0 0 0" rpy="0 -0 0" />
              <geometry>
                  <cylinder radius="0.06" length="0.165" />
              </geometry>
          </collision>
      </link>
      <link name="screen">
          <inertial>
              <mass value="0.440171" />
              <origin xyz="0 0 0" rpy="0 -0 0" />
              <inertia ixx="0.004006" ixy="0.00023" ixz="2e-06" iyy="0.0028" iyz="2.9e-05" izz="0.001509" />
          </inertial>
          <visual>
              <origin xyz="0 -0.00953 -0.0347" rpy="3.14159 -1.57079 3.14159" />
              <geometry>
                  <mesh filename="package://baxter_description/meshes/head/H1.DAE" scale="1 1 1" />
              </geometry>
              <material name="darkred">
                  <texture />
                  <color rgba="0.5 0.1 0.1 1" />
              </material>
          </visual>
          <collision>
              <origin xyz="0 0 0" rpy="0 -0 0" />
              <geometry>
                  <sphere radius="0.001" />
              </geometry>
          </collision>
      </link>
      <link name="sonar_ring">
          <inertial>
              <mass value="0.0001" />
              <origin xyz="0 0 0" rpy="0 -0 0" />
              <inertia ixx="1e-08" ixy="0" ixz="0" iyy="1e-08" iyz="0" izz="1e-08" />
          </inertial>
          <visual>
              <origin xyz="-0.0347 0 0.00953" rpy="0 -0 0" />
              <geometry>
                  <cylinder radius="0.085" length="0.01" />
              </geometry>
              <material name="darkgray">
                  <texture />
                  <color rgba="0.2 0.2 0.2 1" />
              </material>
          </visual>
          <collision>
              <origin xyz="0 0 0" rpy="0 -0 0" />
              <geometry>
                  <sphere radius="0.001" />
              </geometry>
          </collision>
      </link>
      <link name="torso">
          <inertial>
              <mass value="35.3365" />
              <origin xyz="0 0 0" rpy="0 -0 0" />
              <inertia ixx="1.84916" ixy="-0.000354" ixz="-0.154188" iyy="1.66267" iyz="0.003292" izz="0.802239" />
          </inertial>
          <visual>
              <origin xyz="0 0 0" rpy="0 -0 0" />
              <geometry>
                  <mesh filename="package://baxter_description/meshes/torso/base_link.DAE" scale="1 1 1" />
              </geometry>
              <material name="darkgray">
                  <texture />
                  <color rgba="0.2 0.2 0.2 1" />
              </material>
          </visual>
          <collision>
              <origin xyz="-0.065 0 0" rpy="0 -0 0" />
              <geometry>
                  <cylinder radius="0.27" length="0.7" />
              </geometry>
          </collision>
      </link>
      <joint name="collision_head_1" type="fixed">
          <origin xyz="0.11 0 0.75" rpy="0 -0 0" />
          <axis xyz="0 0 0" />
          <parent link="base" />
          <child link="collision_head_link_1" />
      </joint>
      <joint name="collision_head_2" type="fixed">
          <origin xyz="0.11 0 0.75" rpy="0 -0 0" />
          <axis xyz="0 0 0" />
          <parent link="base" />
          <child link="collision_head_link_2" />
      </joint>
      <joint name="display_joint" type="fixed">
          <origin xyz="0 -0.016 0" rpy="0 -0 0" />
          <axis xyz="0 0 0" />
          <parent link="screen" />
          <child link="display" />
      </joint>
      <joint name="dummy" type="fixed">
          <origin xyz="0 0 0" rpy="0 -0 0" />
          <axis xyz="0 0 0" />
          <parent link="head" />
          <child link="dummyhead1" />
      </joint>
      <joint name="head_camera" type="fixed">
          <origin xyz="0.12839 0 0.06368" rpy="1.75057 5.55112e-17 1.5708" />
          <axis xyz="0 0 0" />
          <parent link="head" />
          <child link="head_camera" />
      </joint>
      <joint name="head_nod" type="fixed">
          <origin xyz="0.1227 0 0" rpy="1.75057 5.55112e-17 1.5708" />
          <axis xyz="0 0 0" />
          <parent link="head" />
          <child link="screen" />
      </joint>
      <joint name="head_pan" type="revolute">
          <origin xyz="0.06 0 0.686" rpy="0 -0 0" />
          <axis xyz="0 0 1" />
          <parent link="torso" />
          <child link="head" />
          <dynamics damping="0.7" friction="0" />
          <limit effort="50000" velocity="10000" lower="-1.5708" upper="1.5708" />
      </joint>
      <joint name="left_e0" type="revolute">
          <origin xyz="0.102 0 0" rpy="1.5708 -0 1.5708" />
          <axis xyz="0 0 1" />
          <parent link="left_lower_shoulder" />
          <child link="left_upper_elbow" />
          <dynamics damping="0.7" friction="0" />
          <limit effort="50" velocity="1.5" lower="-3.05418" upper="3.05418" />
      </joint>
      <joint name="left_e0_fixed" type="fixed">
          <origin xyz="0.107 0 0" rpy="1.5708 -0 1.5708" />
          <axis xyz="0 0 0" />
          <parent link="left_lower_shoulder" />
          <child link="left_upper_elbow_visual" />
      </joint>
      <joint name="left_e1" type="revolute">
          <origin xyz="0.069 0 0.26242" rpy="1.57078 -1.57079 -3.14158" />
          <axis xyz="0 0 1" />
          <parent link="left_upper_elbow" />
          <child link="left_lower_elbow" />
          <dynamics damping="0.7" friction="0" />
          <limit effort="50" velocity="1.5" lower="-0.05" upper="2.618" />
      </joint>
      <joint name="left_endpoint" type="fixed">
          <origin xyz="0 0 0.045" rpy="0 -0 0" />
          <axis xyz="0 0 0" />
          <parent link="left_gripper_base" />
          <child link="left_gripper" />
      </joint>
      <joint name="left_gripper_base" type="fixed">
          <origin xyz="0 0 0" rpy="0 -0 0" />
          <axis xyz="0 0 0" />
          <parent link="left_hand" />
          <child link="left_gripper_base" />
      </joint>
      <joint name="left_hand" type="fixed">
          <origin xyz="0 0 0.11355" rpy="0 -0 0" />
          <axis xyz="0 0 0" />
          <parent link="left_wrist" />
          <child link="left_hand" />
      </joint>
      <joint name="left_hand_accelerometer" type="fixed">
          <origin xyz="0.00198 0.000133 -0.0146" rpy="0 -0 0" />
          <axis xyz="0 0 0" />
          <parent link="left_hand" />
          <child link="left_hand_accelerometer" />
      </joint>
      <joint name="left_hand_camera" type="fixed">
          <origin xyz="0.03825 0.012 0.015355" rpy="0 0 -1.5708" />
          <axis xyz="0 0 0" />
          <parent link="left_hand" />
          <child link="left_hand_camera" />
      </joint>
      <joint name="left_hand_camera_axis" type="fixed">
          <origin xyz="0.03825 0.012 0" rpy="0 -0 0" />
          <axis xyz="0 0 0" />
          <parent link="left_hand" />
          <child link="left_hand_camera_axis" />
      </joint>
      <joint name="left_hand_range" type="fixed">
          <origin xyz="0.032 -0.020245 0.0288" rpy="-3.14158 -1.57079 1.57078" />
          <axis xyz="0 0 0" />
          <parent link="left_hand" />
          <child link="left_hand_range" />
      </joint>
      <joint name="left_s0" type="revolute">
          <origin xyz="0.055695 0 0.011038" rpy="0 -0 0" />
          <axis xyz="0 0 1" />
          <parent link="left_arm_mount" />
          <child link="left_upper_shoulder" />
          <dynamics damping="0.7" friction="0" />
          <limit effort="50" velocity="1.5" lower="-1.70168" upper="1.70168" />
      </joint>
      <joint name="left_s1" type="revolute">
          <origin xyz="0.069 0 0.27035" rpy="-1.5708 0 0" />
          <axis xyz="0 0 1" />
          <parent link="left_upper_shoulder" />
          <child link="left_lower_shoulder" />
          <dynamics damping="0.7" friction="0" />
          <limit effort="50" velocity="1.5" lower="-2.147" upper="1.047" />
      </joint>
      <joint name="left_torso_arm_mount" type="fixed">
          <origin xyz="0.0242443 0.220509 0.107602" rpy="-0.00709144 0.0132693 0.790668" />
          <axis xyz="0 0 0" />
          <parent link="torso" />
          <child link="left_arm_mount" />
      </joint>
      <joint name="left_torso_itb_fixed" type="fixed">
          <origin xyz="-0.08897 0.15593 0.389125" rpy="1.5708 9.26536e-05 3.14159" />
          <axis xyz="0 0 0" />
          <parent link="torso" />
          <child link="left_torso_itb" />
      </joint>
      <joint name="left_w0" type="revolute">
          <origin xyz="0.10359 0 0" rpy="1.5708 -0 1.5708" />
          <axis xyz="0 0 1" />
          <parent link="left_lower_elbow" />
          <child link="left_upper_forearm" />
          <dynamics damping="0.7" friction="0" />
          <limit effort="15" velocity="4" lower="-3.059" upper="3.059" />
      </joint>
      <joint name="left_w0_fixed" type="fixed">
          <origin xyz="0.088 0 0" rpy="1.5708 -0 1.5708" />
          <axis xyz="0 0 0" />
          <parent link="left_lower_elbow" />
          <child link="left_upper_forearm_visual" />
      </joint>
      <joint name="left_w0_to_itb_fixed" type="fixed">
          <origin xyz="-0.0565 0 0.12" rpy="-1.5708 -0 1.5708" />
          <axis xyz="0 0 0" />
          <parent link="left_upper_forearm" />
          <child link="left_arm_itb" />
      </joint>
      <joint name="left_w1" type="revolute">
          <origin xyz="0.01 0 0.2707" rpy="1.57078 -1.57079 -3.14158" />
          <axis xyz="0 0 1" />
          <parent link="left_upper_forearm" />
          <child link="left_lower_forearm" />
          <dynamics damping="0.7" friction="0" />
          <limit effort="15" velocity="4" lower="-1.5708" upper="2.094" />
      </joint>
      <joint name="left_w2" type="revolute">
          <origin xyz="0.115975 0 0" rpy="1.5708 -0 1.5708" />
          <axis xyz="0 0 1" />
          <parent link="left_lower_forearm" />
          <child link="left_wrist" />
          <dynamics damping="0.7" friction="0" />
          <limit effort="15" velocity="4" lower="-3.059" upper="3.059" />
      </joint>
      <joint name="pedestal_fixed" type="fixed">
          <origin xyz="0 0 0" rpy="0 -0 0" />
          <axis xyz="0 0 0" />
          <parent link="torso" />
          <child link="pedestal" />
      </joint>
      <joint name="right_e0" type="revolute">
          <origin xyz="0.102 0 0" rpy="1.5708 -0 1.5708" />
          <axis xyz="0 0 1" />
          <parent link="right_lower_shoulder" />
          <child link="right_upper_elbow" />
          <dynamics damping="0.7" friction="0" />
          <limit effort="50" velocity="1.5" lower="-3.05418" upper="3.05418" />
      </joint>
      <joint name="right_e0_fixed" type="fixed">
          <origin xyz="0.107 0 0" rpy="1.5708 -0 1.5708" />
          <axis xyz="0 0 0" />
          <parent link="right_lower_shoulder" />
          <child link="right_upper_elbow_visual" />
      </joint>
      <joint name="right_e1" type="revolute">
          <origin xyz="0.069 0 0.26242" rpy="1.57078 -1.57079 -3.14158" />
          <axis xyz="0 0 1" />
          <parent link="right_upper_elbow" />
          <child link="right_lower_elbow" />
          <dynamics damping="0.7" friction="0" />
          <limit effort="50" velocity="1.5" lower="-0.05" upper="2.618" />
      </joint>
      <joint name="right_endpoint" type="fixed">
          <origin xyz="0 0 0.045" rpy="0 -0 0" />
          <axis xyz="0 0 0" />
          <parent link="right_gripper_base" />
          <child link="right_gripper" />
      </joint>
      <joint name="right_gripper_base" type="fixed">
          <origin xyz="0 0 0" rpy="0 -0 0" />
          <axis xyz="0 0 0" />
          <parent link="right_hand" />
          <child link="right_gripper_base" />
      </joint>
      <joint name="right_hand" type="fixed">
          <origin xyz="0 0 0.11355" rpy="0 -0 0" />
          <axis xyz="0 0 0" />
          <parent link="right_wrist" />
          <child link="right_hand" />
      </joint>
      <joint name="right_hand_accelerometer" type="fixed">
          <origin xyz="0.00198 0.000133 -0.0146" rpy="0 -0 0" />
          <axis xyz="0 0 0" />
          <parent link="right_hand" />
          <child link="right_hand_accelerometer" />
      </joint>
      <joint name="right_hand_camera" type="fixed">
          <origin xyz="0.03825 0.012 0.015355" rpy="0 0 -1.5708" />
          <axis xyz="0 0 0" />
          <parent link="right_hand" />
          <child link="right_hand_camera" />
      </joint>
      <joint name="right_hand_camera_axis" type="fixed">
          <origin xyz="0.03825 0.012 0" rpy="0 -0 0" />
          <axis xyz="0 0 0" />
          <parent link="right_hand" />
          <child link="right_hand_camera_axis" />
      </joint>
      <joint name="right_hand_range" type="fixed">
          <origin xyz="0.032 -0.020245 0.0288" rpy="-3.14158 -1.57079 1.57078" />
          <axis xyz="0 0 0" />
          <parent link="right_hand" />
          <child link="right_hand_range" />
      </joint>
      <joint name="right_s0" type="revolute">
          <origin xyz="0.055695 0 0.011038" rpy="0 -0 0" />
          <axis xyz="0 0 1" />
          <parent link="right_arm_mount" />
          <child link="right_upper_shoulder" />
          <dynamics damping="0.7" friction="0" />
          <limit effort="50" velocity="1.5" lower="-1.70168" upper="1.70168" />
      </joint>
      <joint name="right_s1" type="revolute">
          <origin xyz="0.069 0 0.27035" rpy="-1.5708 0 0" />
          <axis xyz="0 0 1" />
          <parent link="right_upper_shoulder" />
          <child link="right_lower_shoulder" />
          <dynamics damping="0.7" friction="0" />
          <limit effort="50" velocity="1.5" lower="-2.147" upper="1.047" />
      </joint>
      <joint name="right_torso_arm_mount" type="fixed">
          <origin xyz="0.0252076 -0.219127 0.108342" rpy="0.0049102 -0.00625363 -0.785007" />
          <axis xyz="0 0 0" />
          <parent link="torso" />
          <child link="right_arm_mount" />
      </joint>
      <joint name="right_torso_itb_fixed" type="fixed">
          <origin xyz="-0.08897 -0.15593 0.389125" rpy="1.5708 -0 0" />
          <axis xyz="0 0 0" />
          <parent link="torso" />
          <child link="right_torso_itb" />
      </joint>
      <joint name="right_w0" type="revolute">
          <origin xyz="0.10359 0 0" rpy="1.5708 -0 1.5708" />
          <axis xyz="0 0 1" />
          <parent link="right_lower_elbow" />
          <child link="right_upper_forearm" />
          <dynamics damping="0.7" friction="0" />
          <limit effort="15" velocity="4" lower="-3.059" upper="3.059" />
      </joint>
      <joint name="right_w0_fixed" type="fixed">
          <origin xyz="0.088 0 0" rpy="1.5708 -0 1.5708" />
          <axis xyz="0 0 0" />
          <parent link="right_lower_elbow" />
          <child link="right_upper_forearm_visual" />
      </joint>
      <joint name="right_w0_to_itb_fixed" type="fixed">
          <origin xyz="-0.0565 0 0.12" rpy="-1.5708 -0 1.5708" />
          <axis xyz="0 0 0" />
          <parent link="right_upper_forearm" />
          <child link="right_arm_itb" />
      </joint>
      <joint name="right_w1" type="revolute">
          <origin xyz="0.01 0 0.2707" rpy="1.57078 -1.57079 -3.14158" />
          <axis xyz="0 0 1" />
          <parent link="right_upper_forearm" />
          <child link="right_lower_forearm" />
          <dynamics damping="0.7" friction="0" />
          <limit effort="15" velocity="4" lower="-1.5708" upper="2.094" />
      </joint>
      <joint name="right_w2" type="revolute">
          <origin xyz="0.115975 0 0" rpy="1.5708 -0 1.5708" />
          <axis xyz="0 0 1" />
          <parent link="right_lower_forearm" />
          <child link="right_wrist" />
          <dynamics damping="0.7" friction="0" />
          <limit effort="15" velocity="4" lower="-3.059" upper="3.059" />
      </joint>
      <joint name="sonar_s0" type="fixed">
          <origin xyz="0.0947 0 0.817" rpy="0 -0 0" />
          <axis xyz="0 0 0" />
          <parent link="torso" />
          <child link="sonar_ring" />
      </joint>
      <joint name="torso_t0" type="fixed">
          <origin xyz="0 0 0" rpy="0 -0 0" />
          <axis xyz="0 0 0" />
          <parent link="base" />
          <child link="torso" />
          <limit effort="50000" velocity="10000" lower="-3.01" upper="3.01" />
      </joint>
  </robot>
  
